## Exceptions异常

`Dart`代码可以抛出和捕获`exception`(异常)。异常表示一些未知的错误情况。如果未捕获到异常，则异常会抛出，导致抛出异常的代码终止执行。

与`Java`相比，`Dart`的所有异常都是未经检查的异常。方法不会声明它们可能引发哪些异常，也不要求捕获任何异常。

`Dart`提供了`Exception`和`Error`类型，以及许多预定义的子类型。当然你可以定义自己的异常。 但是，Dart程序可以将任何非`null`对象（不仅仅是`Exception`和`Error`对象）作为异常抛出。

### throw

如下是抛出异常的示例，生产环境代码通常会实现 [Error](https://api.dart.dev/stable/2.12.2/dart-core/Error-class.html) 或 [Exception](https://api.dart.dev/stable/2.12.2/dart-core/Exception-class.html) 类型的异常抛出。

```Dart
void test(int a) {
  switch (a) {
    case -1:
      // 抛出 exception 异常
      throw FormatException('a 不能为 -1');
    case 0:
      throw 'a 不能为 0';    // 可以抛出任意对象
    case 100:
      throw UnimplementedError();
    default:
      print('num is $a');
      break;
  }
}

test(66);   // 打印：num is 66
test(-1);
test(0);
test(100);
test(99);   // 不会打印 （由于上面代码抛出异常）
```

抛出异常是一个表达式，所以可以在`=>`语句以及允许表达式的其他任何地方抛出异常：

```Dart
void distanceTo(Point other) => throw UnimplementedError();
```

### catch

捕获异常会阻止该异常的传播（除非您重新抛出该异常）。可以通过捕获异常的机会来处理该异常：

```Dart
try {
  test(-1);
  // 使用 on 来指定异常类型， 使用 catch 来 捕获异常对象。
  // e为引发的异常对象，s为堆栈信息
} on Exception catch (e, s) {
  print('Exception details: $e');     
  print('Stack trace:\n $s');
}

test(99);       // 异常被捕获，函数会继续执行
// 打印：
// Exception details: FormatException: a 不能为 -1
// num is 99
```

```Dart
try {
  test(100);
} on Error catch (e) {
  print(e);     // 打印：UnimplementedError: a 不能为 100
}
```

```Dart
try {
  test(0);
} on Exception catch (e) {
  print(e);
} catch (e, s) {   // 处理任意类型
  print('$e - ${e.runtimeType}');       // 打印：a 不能为 0 - String
}
```

* 如果仅需要部分处理异常， 那么可以使用关键字 `rethrow` 将异常重新抛出。

```Dart
try {
  test(-1);
} on Exception catch (e) {
  print(e);   // FormatException: a 不能为 -1
  rethrow;
} 
test(99);   // 不会打印，因为异常被重新抛出了
```

### finally

为确保某些代码无论是否引发异常都可以运行，请使用`finally`子句。 如果没有`catch`子句与该异常匹配，则在`finally`子句运行后传播该异常：

* 如下代码未抛出异常，`finally`子句也会执行：

```Dart
try {
  test(66);
} finally {
  print('xxxxx'); 
} 

test(99);   
// 打印：
// xxxxx
// num is 99
```

* 如下代码异常被捕获，`finally`子句也会执行：

```Dart
try {
  test(-1);
} on Exception catch (e) {
  print(e); 
} finally {
  print('xxxxx'); 
} 
test(99); 

// 打印：  
// FormatException: a 不能为 -1
// xxxxx
// num is 99
```

* 如下代码异常未被捕获，异常会在 finally 执行完成后，再次被抛出：

```Dart
try {
  test(-1);
} finally {
  print('xxxxx'); 
} 
test(99);   // 不会执行
// 打印：
// xxxxx
```